Workbook

Sheet Registro_Horas
A1: Mes | B1: Cliente | C1: Horas | D1: Precio/Hora | E1: Total | F1: Enviada | G1: Pagado | H1: Comentarios
A2: Enero | B2: Diettest | C2: 7 | D2: 26 | E2: =C2*D2 -> 182 | F2: TRUE | G2: TRUE | H2: Pago mensual de SEO
A3: Enero | B3: Venttus Illusion | C3: 11 | D3: 30 | E3: =C3*D3 -> 330 | F3: TRUE | G3: TRUE | H3: Pago mensual de Mantenimiento
A4: Enero | B4: Templo del Masaje | C4: =2 + (0/60) -> 2 | D4: 30 | E4: =C4*D4 -> 60 | F4: TRUE | G4: TRUE | H4: Cambios en Webs (2h 0min)
A5: Enero | B5: Findall | C5: =5 + (0/60) -> 5 | D5: 26 | E5: =C5*D5 -> 130 | F5: TRUE | G5: TRUE | H5: Traducciones (1h) + Vista movil (3h) + Página Web (1h)
A6: Enero | B6: Clases Alicia | C6: =3 + (40/60) -> 3.6666667 | D6: 30 | E6: =C6*D6 -> 110 | F6: TRUE | G6: TRUE | H6: Martes 13, 12:00-13:30 + Miercoles 21, 12:00 - 13:00 + Martes 27, 12:00 - 13:10
A7: Enero | B7: Chigo Bienestar | C7: 35.25 | D7: 30 | E7: =C7*D7 -> 1057.5 | F7: TRUE | G7: TRUE | H7: Primer pago de EPCO Freemium
A8: Febrero | B8: Chigo Bienestar | C8: 35.25 | D8: 30 | E8: =C8*D8 -> 1057.5 | F8: TRUE | G8: TRUE | H8: Segundo pago de EPCO Freemium
A9: Febrero | B9: Diettest | C9: 7 | D9: 26 | E9: =C9*D9 -> 182 | F9: TRUE | G9: TRUE | H9: Pago mensual de SEO
A10: Febrero | B10: Venttus Illusion | C10: 11 | D10: 30 | E10: =C10*D10 -> 330 | F10: TRUE | G10: TRUE | H10: Pago mensual de Mantenimiento
A11: Febrero | B11: Label Concierge | C11: 3 | D11: 35 | E11: =C11*D11 -> 105 | F11: TRUE | G11: TRUE | H11: Recuperar documentos y usuarios
A12: Febrero | B12: Templo del Masaje | C12: =5 + (30/60) -> 5.5 | D12: 30 | E12: =C12*D12 -> 165 | F12: TRUE | G12: TRUE | H12: Cambios en Webs (3h 0min) + Cambios en Extranet de Nobel (2h 30min)
A13: Febrero | B13: Clases Alicia | C13: =2 + (10/60) -> 2.1666667 | D13: 30 | E13: =C13*D13 -> 65 | F13: TRUE | G13: TRUE | H13: Viernes 06, 9:40-10:50 + Martes 10, 11:40 a 12:40
A14: Febrero | B14: Jacinto | C14: =24.6 -> 24.6 | D14: 30 | E14: =C14*D14 -> 738 | F14: TRUE | G14: TRUE | H14: Primer pago de Jacinto y APP
A15: Febrero | B15: Dasana | C15: 45 | D15: 30 | E15: =C15*D15 -> 1350 | F15: TRUE | G15: TRUE | H15: Pago por Make y Brevo de Dasana
A16: Febrero | B16: Daniel Oñate | C16: 63.3 | D16: 26 | E16: =C16*D16 -> 1645.8 | F16: TRUE | G16: TRUE | H16: Primer pago APP Daniel
A17: Marzo | B17: Jacinto | C17: =24.6 -> 24.6 | D17: 30 | E17: =C17*D17 -> 738 | F17: TRUE | G17: TRUE | H17: Segundo pago de Jacinto y APP
A18: Marzo | B18: Venttus Illusion | C18: 6 | D18: 30 | E18: =C18*D18 -> 180 | F18: TRUE | G18: TRUE | H18: Pago mensual de Mantenimiento
A19: Marzo | B19: Templo del Masaje | C19: =2 + (0/60) -> 2 | D19: 30 | E19: =C19*D19 -> 60 | F19: TRUE | G19: TRUE | H19: Cambios en Webs (2h 0min)
A20: Marzo | B20: Daniel Oñate | C20: 84.4 | D20: 26 | E20: =C20*D20 -> 2194.4 | F20: TRUE | G20: TRUE | H20: Segundo pago APP Daniel
A21: Marzo | B21: Yolanda Jarasclub | C21: 65 | D21: 30 | E21: =C21*D21 -> 1950 | F21: TRUE | G21: TRUE | H21: Primer pago JarasClub Yolanda
A22: Marzo | B22: Daniel Oñate | C22: 63.3 | D22: 26 | E22: =C22*D22 -> 1645.8 | F22: TRUE | G22: TRUE | H22: Tercero pago APP Daniel
A23: Abril | B23: Diettest | C23: 4 | D23: 26 | E23: =C23*D23 -> 104 | F23: TRUE | G23: TRUE | H23: Pago mensual de SEO
A24: Abril | B24: Chigo Bienestar | C24: 25.5 | D24: 30 | E24: =C24*D24 -> 765 | F24: TRUE | G24: TRUE | H24: Desarrollo de decathlon
A25: Abril | B25: 2 Connect | C25: =75 + (30/60) -> 75.5 | D25: 26 | E25: =C25*D25 -> 1963 | F25: TRUE | G25: TRUE | H25: Último Pago 2 Connect APP
A26: Abril | B26: Somos Aventura | C26: =72.83 -> 72.83 | D26: 30 | E26: =C26*D26 -> 2184.9 | F26: TRUE | G26: TRUE | H26: Último Pago 2 Connect APP
A27: Abril | B27: Templo del Masaje | C27: =2 + (0/60) -> 2 | D27: 30 | E27: =C27*D27 -> 60 | F27: TRUE | G27: TRUE | H27: Cambios en Webs (2h 0min)
A28: Abril | B28: Diettest | C28: =7 + (0/60) -> 7 | D28: 26 | E28: =C28*D28 -> 182 | F28: TRUE | G28: TRUE | H28: Pago Reuniones Google ADS y Google Tag Manager (3h 30min) + Bakcups 1h 30min + Reunion para Zoom, Cancelar Reservas, Meta/Google ADS (2h)
A29: Mayo | B29: Travel Meet | C29: 62.1 | D29: 30 | E29: =C29*D29 -> 1863 | F29: TRUE | G29: TRUE | H29: Primer pago de Travel Meet
A30: Mayo | B30: Tartuga | C30: =37 -> 37 | D30: 30 | E30: =C30*D30 -> 1110 | F30: TRUE | G30: TRUE | H30: Tercer pago de Tartuga
A31: Mayo | B31: Dasana | C31: 30 | D31: 30 | E31: =C31*D31 -> 900 | F31: TRUE | G31: TRUE | H31: Pago final de Dasana
A32: Mayo | B32: We Offsite | C32: =25 -> 25 | D32: 30 | E32: =C32*D32 -> 750 | F32: TRUE | G32: TRUE | H32: Primer pago página web de Roberto Astro
A33: Mayo | B33: TODO VA BIEN MJM SL | C33: =13.5 -> 13.5 | D33: 30 | E33: =C33*D33 -> 405 | F33: TRUE | G33: TRUE | H33: Primer pago página web de Maria Jose Astro
A34: Mayo | B34: FUNDACION VISUAL TEAF | C34: 110.1 | D34: 30 | E34: =C34*D34 -> 3303 | F34: FALSE | G34: FALSE | H34: Primer pago plataforma fundacion
A35: Mayo | B35: Daniel Oñate | C35: 6 | D35: 30 | E35: =C35*D35 -> 180 | F35: TRUE | G35: TRUE | H35: Pago por panel de administración
A36: Mayo | B36: PAVIMPRESOCAT | C36: =26.5 -> 26.5 | D36: 30 | E36: =C36*D36 -> 795 | F36: TRUE | G36: TRUE | H36: Primer pago página web de PAVIMPRESOCAT
A37: Junio | B37: 2 Connect | C37: =39 + (30/60) -> 39.5 | D37: 30 | E37: =C37*D37 -> 1185 | F37: TRUE | G37: TRUE | H37: Plataforma Admin de 2Connect
A38: Junio | B38: We Offsite | C38: =25 -> 25 | D38: 30 | E38: =C38*D38 -> 750 | F38: TRUE | G38: TRUE | H38: Último pago página web de Roberto Astro
A39: Junio | B39: PAVIMPRESOCAT | C39: =26.5 -> 26.5 | D39: 30 | E39: =C39*D39 -> 795 | F39: TRUE | G39: TRUE | H39: Último pago página web de PAVIMPRESOCAT
A40: Junio | B40: TODO VA BIEN MJM SL | C40: =13.5 -> 13.5 | D40: 30 | E40: =C40*D40 -> 405 | F40: TRUE | G40: TRUE | H40: Primer pago página web de Maria Jose Astro
...

Sheet Resumen_Mensual
A1: Mes | B1: Ingresos Totales | C1: IVA (21%) | D1: Cuota Autónomos | E1: Otros Gastos | F1: Beneficio Neto | H1: IRPF MENSUAL
A2: Enero | B2: =SUMIF(Registro_Horas!A:A,A2,Registro_Horas!E:E) -> 1869.5 | C2: =(B2*0.21) - (110*0.21) -> 369.495 | D2: 205 | E2: 390 | F2: =B2-D2-E2-H2 -> 1151.335 | H2: =(B2 * 0.07) - (110*0.07) -> 123.165
A3: Febrero | B3: =SUMIF(Registro_Horas!A:A,A3,Registro_Horas!E:E) -> 5638.3 | C3: =B3*0.21 -> 1184.043 | D3: 205 | E3: 390 | F3: =B3-D3-E3-H3 -> 4648.619 | H3: =B3 * 0.07 -> 394.681
A4: Marzo | B4: =SUMIF(Registro_Horas!A:A,A4,Registro_Horas!E:E) -> 6768.2 | C4: =B4*0.21 -> 1421.322 | D4: 205 | E4: 390 | F4: =B4-D4-E4-H4 -> 5699.426 | H4: =B4 * 0.07 -> 473.774
A5: Abril | B5: =SUMIF(Registro_Horas!A:A,A5,Registro_Horas!E:E) -> 5258.9 | C5: =B5*0.21 -> 1104.369 | D5: 205 | E5: 390 | F5: =B5-D5-E5-H5 -> 4295.777 | H5: =B5 * 0.07 -> 368.123
A6: Mayo | B6: =SUMIF(Registro_Horas!A:A,A6,Registro_Horas!E:E) -> 9306 | C6: =B6*0.21 -> 1954.26 | D6: 205 | E6: 390 | F6: =B6-D6-E6-H6 -> 8059.58 | H6: =B6 * 0.07 -> 651.42
A7: Junio | B7: =SUMIF(Registro_Horas!A:A,A7,Registro_Horas!E:E) -> 7718.1 | C7: =B7*0.21 -> 1620.801 | D7: 205 | E7: 390 | F7: =B7-D7-E7-H7 -> 6582.833 | H7: =B7 * 0.07 -> 540.267
A8: Julio | B8: =SUMIF(Registro_Horas!A:A,A8,Registro_Horas!E:E) -> 13407.54 | C8: =B8*0.21 -> 2815.5834 | D8: 205 | E8: 390 | F8: =B8-D8-E8-H8 -> 11874.012 | H8: =B8 * 0.07 -> 938.5278
A9: Agosto | B9: =SUMIF(Registro_Horas!A:A,A9,Registro_Horas!E:E) -> 6603.6 | C9: =B9*0.21 -> 1386.756 | D9: 205 | E9: 390 | F9: =B9-D9-E9-H9 -> 5546.348 | H9: =B9 * 0.07 -> 462.252
A10: Septiembre | B10: =SUMIF(Registro_Horas!A:A,A10,Registro_Horas!E:E) -> 4806 | C10: =B10*0.21 -> 1009.26 | F10: =B10-D10-E10-H10 -> 4469.58 | H10: =B10 * 0.07 -> 336.42
A11: Octubre | B11: =SUMIF(Registro_Horas!A:A,A11,Registro_Horas!E:E) -> 2184.9 | C11: =B11*0.21 -> 458.829 | F11: =B11-D11-E11-H11 -> 2031.957 | H11: =B11 * 0.07 -> 152.943
A12: Noviembre | B12: =SUMIF(Registro_Horas!A:A,A12,Registro_Horas!E:E) -> 0 | C12: =B12*0.21 -> 0 | F12: =B12-D12-E12-H12 -> 0 | H12: =B12 * 0.07 -> 0
A13: Diciembre | B13: =SUMIF(Registro_Horas!A:A,A13,Registro_Horas!E:E) -> 0 | C13: =B13*0.21 -> 0 | F13: =B13-D13-E13-H13 -> 0 | H13: =B13 * 0.07 -> 0
A15: TOTAL ANUAL | B15: =SUM(B2:B13) -> 63561.04 | C15: =SUM(C2:C13) -> 13324.718 | D15: =SUM(D2:D13) -> 1640 | F15: =SUM(F2:F13) -> 54359.467 | H15: =SUM(H2:H13) -> 4441.5728

Sheet Dashboard
A1: RESUMEN ANUAL
A3: Total Ingresos: | B3: =SUM(Resumen_Mensual!B2:B13) -> 63561.04
A4: Total IVA: | B4: =SUM(Resumen_Mensual!C2:C13) -> 13324.718
A5: Media Mensual: | B5: =AVERAGE(Resumen_Mensual!F2:F13) -> 4529.9556
A6: Total Horas: | B6: =SUM(Registro_Horas!C:C) -> 2169.4933

Sheet Registro_Horas_Desarrollos
A1: Mes | B1: Cliente | C1: Horas | D1: Comentarios
